Workbook
Name CHAMBRE: #REF!
Name CHAMBRE: #REF!
Name CHAMBRE: #REF!
Name eve: #REF!
Name ID: "60144a54-86a0-47d2-a174-bff17ff1ab1b"
Name ID: "4b87f5f1-95ae-4ea3-9982-41c83bacc0d4"
Name ID: "995d5dcf-c38c-4d72-8146-68eeb01e9d77"
Name ID: "33ac380a-637f-44ec-b090-8e76a0d8b7d2"
Name ID: "20541fec-2ad6-49f3-88f8-036f51f101c6"
Name ID: "2744ba14-1e13-44e3-b85d-610e97cc9436"
Name ID: "34de952b-5782-4085-9ff3-4197e80d0519"
Name ID: "5dfb4f60-dfef-478e-b572-6d84ca11220c"
Name ID: "a48ca980-bd16-4857-83c5-04df395cf5df"
Name ID: "4856a158-f6a0-42fd-8985-97a75c2ff6e9"
Name ID: "84f1fda5-4f42-4da6-97ae-83d72f1ee8b5"
Name ID: "46b5d57d-835c-45cd-a153-8db7dfdee164"
Name ID: "9db657a3-4005-4942-9644-3312b6a9af97"
Name ID: "c7f46df9-ea21-4c82-9ae2-b19cd1e99ee9"
Name ID: "b72319b6-5397-4665-9638-78492301febd"
Name ID: "0f85ba89-06c7-47b3-adfd-ec9143cb315e"
Name ID: "3e3c12a1-b6b1-41fd-8aaa-8c64ead3b672"
Name ID: "14811328-6be0-4bf0-8db5-a5ae35195543"
Name ok: #REF!
Name ok: #REF!
Name tata: #REF!
Name tata: #REF!
Name toto: #REF!

Sheet Feuil4
A1: ANNEE SCOLAIRE 2009-2010
B3: ZONE A | C3: ZONE B | D3: ZONE C
A4: Rentrée des enseignants (*) | B4: Mardi 1er septembre 2009
A5: Rentrée scolaire des élèves | B5: Mercredi 2 septembre 2009
A6: Toussaint | B6: Samedi 24 octobre 2009
B7: Jeudi 5 novembre 2009
A8: Noël | B8: Samedi 19 décembre 2009
B9: Lundi 4 janvier 2010
A10: Hiver | B10: Samedi 13 février 2010 | C10: Samedi 6 février 2010 | D10: Samedi 20 février 2010
B11: Lundi 1 mars 2010 | C11: Lundi 22 février 2010 | D11: Lundi 8 mars 2010
A12: Printemps | B12: Samedi 10 avril 2010 | C12: Samedi 3 avril 2010 | D12: Samedi 17 avril 2010
B13: Lundi 26 avril 2010 | C13: Lundi 19 avril 2010 | D13: Lundi 3 mai 2010
A14: Début des vacances d'été (**) | B14: Vendredi 2 juillet 2010
A15: (*) Deux demi-journées (ou un horaire équivalent), prises en dehors des heures de cours, seront dégagées, avant les vacances de la Toussaint, afin de permettre de prolonger la réflexion engagée lors de la journée de prérentrée.
A16: (**) Les enseignants appelés à participer aux opérations liées aux examens sont en service jusqu'à la date fixée pour la clôture de ces examens par la note de service établissant le calendrier de la session.
A17: Le départ en vacances a lieu après la classe, la reprise des cours le matin des jours indiqués.
A18: Lorsque les vacances débutent un mercredi, pour les élèves qui n'ont pas cours ce jour-là, le départ a lieu le mardi après les cours et la rentrée le jeudi.

Sheet 1,6
B1: 40179 | C1: 40180 | D1: 40181 | E1: 40182 | F1: 40183 | G1: 40184 | H1: 40185 | I1: 40186 | J1: 40187 | K1: 40188 | L1: 40189 | M1: 40190 | N1: 40191 | O1: 40192 | P1: 40193 | Q1: 40194 | R1: 40195 | S1: 40196 | T1: 40197 | U1: 40198 | V1: 40199 | W1: 40200 | X1: 40201 | Y1: 40202 | Z1: 40203 | AA1: 40204 | AB1: 40205 | AC1: 40206 | AD1: 40207 | AE1: 40208 | AF1: 40209
A2: Ind Cash | B2: 1716.4235 | C2: 1981.5529 | D2: 926.96471 | E2: 0 | F2: 0 | G2: 0 | H2: 0 | I2: 0 | J2: 0 | K2: 0 | L2: 0 | M2: 0 | N2: 0 | O2: 0 | P2: 0 | Q2: 0 | R2: 0 | S2: 0 | T2: 0 | U2: 0 | V2: 0 | W2: 0 | X2: 0 | Y2: 0 | Z2: 0 | AA2: 0 | AB2: 0 | AC2: 0 | AD2: 0 | AE2: 0 | AF2: 0
A3: Ind Résa | B3: 4016.2824 | C3: 4005.2706 | D3: 1280.0941 | E3: 0 | F3: 0 | G3: 0 | H3: 0 | I3: 0 | J3: 0 | K3: 0 | L3: 0 | M3: 0 | N3: 0 | O3: 0 | P3: 0 | Q3: 0 | R3: 0 | S3: 0 | T3: 0 | U3: 0 | V3: 0 | W3: 0 | X3: 0 | Y3: 0 | Z3: 0 | AA3: 0 | AB3: 0 | AC3: 0 | AD3: 0 | AE3: 0 | AF3: 0
A5: G. AD | B5: 0 | C5: 0 | D5: 0 | E5: 0 | F5: 0 | G5: 0 | H5: 0 | I5: 0 | J5: 0 | K5: 0 | L5: 0 | M5: 0 | N5: 0 | O5: 0 | P5: 0 | Q5: 0 | R5: 0 | S5: 0 | T5: 0 | U5: 0 | V5: 0 | W5: 0 | X5: 0 | Y5: 0 | Z5: 0 | AA5: 0 | AB5: 0 | AC5: 0 | AD5: 0 | AE5: 0 | AF5: 0
A6: G Jeune | B6: 0 | C6: 0 | D6: 0 | E6: 0 | F6: 0 | G6: 0 | H6: 0 | I6: 0 | J6: 0 | K6: 0 | L6: 0 | M6: 0 | N6: 0 | O6: 0 | P6: 0 | Q6: 0 | R6: 0 | S6: 0 | T6: 0 | U6: 0 | V6: 0 | W6: 0 | X6: 0 | Y6: 0 | Z6: 0 | AA6: 0 | AB6: 0 | AC6: 0 | AD6: 0 | AE6: 0 | AF6: 0
A8: Nocturne | B8: 0 | C8: 18.823529 | D8: 18.823529 | E8: 0 | F8: 0 | G8: 0 | H8: 0 | I8: 0 | J8: 0 | K8: 0 | L8: 0 | M8: 0 | N8: 0 | O8: 0 | P8: 0 | Q8: 0 | R8: 0 | S8: 0 | T8: 0 | U8: 0 | V8: 0 | W8: 0 | X8: 0 | Y8: 0 | Z8: 0 | AA8: 0 | AB8: 0 | AC8: 0 | AD8: 0 | AE8: 0 | AF8: 0
A9: Pass | B9: 112.94118 | C9: 112.94118 | D9: 112.94118 | E9: 0 | F9: 0 | G9: 0 | H9: 0 | I9: 0 | J9: 0 | K9: 0 | L9: 0 | M9: 0 | N9: 0 | O9: 0 | P9: 0 | Q9: 0 | R9: 0 | S9: 0 | T9: 0 | U9: 0 | V9: 0 | W9: 0 | X9: 0 | Y9: 0 | Z9: 0 | AA9: 0 | AB9: 0 | AC9: 0 | AD9: 0 | AE9: 0 | AF9: 0
A10: TA + Cong | B10: 16 | C10: 94.117647 | D10: 541.17647 | E10: 0 | F10: 658.82353 | G10: 0 | H10: 188.23529 | I10: 0 | J10: 21.647059 | K10: 0 | L10: 0 | M10: 0 | N10: 0 | O10: 322.82353 | P10: 59.294118 | Q10: 0 | R10: 0 | S10: 28.235294 | T10: 0 | U10: 235.29412 | V10: 941.17647 | W10: 94.117647 | X10: 68.705882 | Y10: 0 | Z10: 0 | AA10: 0 | AB10: 141.17647 | AC10: 0 | AD10: 0 | AE10: 376.47059 | AF10: 376.47059
A11: Invités | B11: 635.29412 | C11: 658.82353 | D11: 357.64706 | E11: 0 | F11: 0 | G11: 0 | H11: 0 | I11: 0 | J11: 0 | K11: 0 | L11: 0 | M11: 0 | N11: 0 | O11: 0 | P11: 0 | Q11: 0 | R11: 0 | S11: 0 | T11: 0 | U11: 0 | V11: 0 | W11: 0 | X11: 0 | Y11: 0 | Z11: 0 | AA11: 0 | AB11: 0 | AC11: 0 | AD11: 0 | AE11: 0 | AF11: 0
B13: 40210 | C13: 40211 | D13: 40212 | E13: 40213 | F13: 40214 | G13: 40215 | H13: 40216 | I13: 40217 | J13: 40218 | K13: 40219 | L13: 40220 | M13: 40221 | N13: 40222 | O13: 40223 | P13: 40224 | Q13: 40225 | R13: 40226 | S13: 40227 | T13: 40228 | U13: 40229 | V13: 40230 | W13: 40231 | X13: 40232 | Y13: 40233 | Z13: 40234 | AA13: 40235 | AB13: 40236 | AC13: 40237
A14: Ind Cash | B14: 0 | C14: 0 | D14: 0 | E14: 0 | F14: 0 | G14: 1454.1176 | H14: 960.84706 | I14: 790.68235 | J14: 1030.8706 | K14: 648.09412 | L14: 843.76471 | M14: 782.11765 | N14: 1798.8706 | O14: 1515.3882 | P14: 814.68235 | Q14: 1144.9412 | R14: 1110.1176 | S14: 1110.4 | T14: 1009.7882 | U14: 1221.9294 | V14: 1244.8941 | W14: 515.85882 | X14: 872.47059 | Y14: 765.74118 | Z14: 813.36471 | AA14: 694.11765 | AB14: 1259.2 | AC14: 888.65882
A15: Ind Résa | B15: 0 | C15: 0 | D15: 0 | E15: 0 | F15: 0 | G15: 1739.2941 | H15: 1219.8588 | I15: 1922.7294 | J15: 1506.5412 | K15: 1371.6706 | L15: 1113.8824 | M15: 2033.8824 | N15: 1852.8941 | O15: 2660.6118 | P15: 2979.2 | Q15: 3608.9412 | R15: 3172.2353 | S15: 2489.6 | T15: 2690.9176 | U15: 3095.2471 | V15: 2483.1059 | W15: 3424.8471 | X15: 3134.1176 | Y15: 2175.4353 | Z15: 3916.9882 | AA15: 3268.2353 | AB15: 2911.1529 | AC15: 2492.9882
A17: G. AD | B17: 0 | C17: 0 | D17: 0 | E17: 0 | F17: 0 | G17: 153.41176 | H17: 145.88235 | I17: 57.411765 | J17: 0 | K17: 0 | L17: 0 | M17: 0 | N17: 178.82353 | O17: 193.88235 | P17: 0 | Q17: 0 | R17: 65.882353 | S17: 98.823529 | T17: 0 | U17: 336 | V17: 292.70588 | W17: 73.411765 | X17: 60.235294 | Y17: 0 | Z17: 49.882353 | AA17: 17.882353 | AB17: 355.76471 | AC17: 367.05882
A18: G Jeune | B18: 0 | C18: 0 | D18: 0 | E18: 0 | F18: 0 | G18: 0 | H18: 23.529412 | I18: 82.823529 | J18: 281.41176 | K18: 457.41176 | L18: 327.52941 | M18: 634.35294 | N18: 384.94118 | O18: 49.882353 | P18: 14.117647 | Q18: 197.64706 | R18: 120.47059 | S18: 323.76471 | T18: 496 | U18: 371.76471 | V18: 221.17647 | W18: 235.29412 | X18: 235.29412 | Y18: 448.94118 | Z18: 112.94118 | AA18: 545.88235 | AB18: 334.11765 | AC18: 23.529412
A20: Nocturne | B20: 0 | C20: 0 | D20: 0 | E20: 0 | F20: 0 | G20: 0 | H20: 0 | I20: 0 | J20: 0 | K20: 0 | L20: 0 | M20: 0 | N20: 0 | O20: 0 | P20: 0 | Q20: 0 | R20: 0 | S20: 0 | T20: 0 | U20: 0 | V20: 0 | W20: 0 | X20: 0 | Y20: 0 | Z20: 0 | AA20: 0 | AB20: 0 | AC20: 0
A21: Pass | B21: 0 | C21: 0 | D21: 0 | E21: 0 | F21: 0 | G21: 112.94118 | H21: 141.17647 | I21: 94.117647 | J21: 94.117647 | K21: 94.117647 | L21: 94.117647 | M21: 94.117647 | N21: 141.17647 | O21: 94.117647 | P21: 94.117647 | Q21: 94.117647 | R21: 94.117647 | S21: 94.117647 | T21: 94.117647 | U21: 141.17647 | V21: 94.117647 | W21: 70.588235 | X21: 70.588235 | Y21: 56.470588 | Z21: 37.647059 | AA21: 37.647059 | AB21: 70.588235 | AC21: 70.588235
A22: TA + Cong | B22: 0 | C22: 0 | D22: 0 | E22: 235.29412 | F22: 0 | G22: 11.294118 | H22: 11.294118 | I22: 37.647059 | J22: 65.882353 | K22: 0 | L22: 0 | M22: 37.647059 | N22: 0 | O22: 0 | P22: 0 | Q22: 0 | R22: 0 | S22: 0 | T22: 0 | U22: 0 | V22: 0 | W22: 0 | X22: 0 | Y22: 0 | Z22: 0 | AA22: 0 | AB22: 282.35294 | AC22: 0
A23: Invités | B23: 0 | C23: 0 | D23: 0 | E23: 0 | F23: 0 | G23: 112.94118 | H23: 37.647059 | I23: 18.823529 | J23: 376.47059 | K23: 65.882353 | L23: 18.823529 | M23: 451.76471 | N23: 56.470588 | O23: 75.294118 | P23: 18.823529 | Q23: 470.58824 | R23: 112.94118 | S23: 395.29412 | T23: 23.529412 | U23: 94.117647 | V23: 70.588235 | W23: 42.352941 | X23: 517.64706 | Y23: 47.058824 | Z23: 541.17647 | AA23: 37.647059 | AB23: 37.647059 | AC23: 47.058824
B25: 40238 | C25: 40239 | D25: 40240 | E25: 40241 | F25: 40242 | G25: 40243 | H25: 40244 | I25: 40245 | J25: 40246 | K25: 40247 | L25: 40248 | M25: 40249 | N25: 40250 | O25: 40251 | P25: 40252 | Q25: 40253 | R25: 40254 | S25: 40255 | T25: 40256 | U25: 40257 | V25: 40258 | W25: 40259 | X25: 40260 | Y25: 40261 | Z25: 40262 | AA25: 40263 | AB25: 40264 | AC25: 40265 | AD25: 40266 | AE25: 40267 | AF25: 40268
A26: Ind Cash | B26: 625.41176 | C26: 726.11765 | D26: 677.64706 | E26: 753.50588 | F26: 713.12941 | G26: 1284.6118 | H26: 615.15294 | I26: 131.01176 | J26: 159.05882 | K26: 173.74118 | L26: 151.71765 | M26: 156.42353 | N26: 1939.0118 | O26: 1135.6235 | P26: 148.98824 | Q26: 114.25882 | R26: 137.97647 | S26: 194.63529 | T26: 157.27059 | U26: 2035.0118 | V26: 1158.0235 | W26: 237.36471 | X26: 208.28235 | Y26: 189.92941 | Z26: 203.76471 | AA26: 204.98824 | AB26: 2103.5294 | AC26: 1193.2235 | AD26: 211.57647 | AE26: 300.8 | AF26: 184.18824
A27: Ind Résa | B27: 1869.6471 | C27: 1904.4706 | D27: 1269.6471 | E27: 2123.6706 | F27: 1627.5765 | G27: 2156.3294 | H27: 1812.1412 | I27: 495.81176 | J27: 416.94118 | K27: 425.78824 | L27: 418.63529 | M27: 370.63529 | N27: 2434.6353 | O27: 1880.8471 | P27: 470.30588 | Q27: 457.03529 | R27: 417.31765 | S27: 482.07059 | T27: 574.96471 | U27: 3129.2235 | V27: 2097.5059 | W27: 479.81176 | X27: 482.54118 | Y27: 453.83529 | Z27: 449.41176 | AA27: 534.77647 | AB27: 2757.6471 | AC27: 2032.1882 | AD27: 484.89412 | AE27: 486.96471 | AF27: 346.63529
A29: G. AD | B29: 0 | C29: 0 | D29: 0 | E29: 55.529412 | F29: 47.058824 | G29: 376.47059 | H29: 211.76471 | I29: 65.882353 | J29: 42.352941 | K29: 0 | L29: 37.647059 | M29: 0 | N29: 1176.4706 | O29: 1294.1176 | P29: 84.705882 | Q29: 0 | R29: 150.58824 | S29: 0 | T29: 0 | U29: 1258.3529 | V29: 1082.3529 | W29: 0 | X29: 51.764706 | Y29: 47.058824 | Z29: 19.764706 | AA29: 0 | AB29: 2757.6471 | AC29: 1981.1765 | AD29: 18.823529 | AE29: 28.235294 | AF29: 21.647059
A30: G Jeune | B30: 0 | C30: 305.88235 | D30: 324.70588 | E30: 353.88235 | F30: 776.47059 | G30: 367.05882 | H30: 248.47059 | I30: 122.35294 | J30: 136.47059 | K30: 592.94118 | L30: 395.29412 | M30: 1077.6471 | N30: 965.64706 | O30: 1327.0588 | P30: 169.41176 | Q30: 560.94118 | R30: 678.58824 | S30: 457.41176 | T30: 1237.6471 | U30: 969.41176 | V30: 191.05882 | W30: 288.94118 | X30: 856.47059 | Y30: 2169.4118 | Z30: 1004.2353 | AA30: 1969.8824 | AB30: 1548.2353 | AC30: 607.05882 | AD30: 797.17647 | AE30: 1530.3529 | AF30: 2602.3529
A32: Nocturne | B32: 0 | C32: 0 | D32: 0 | E32: 0 | F32: 0 | G32: 0 | H32: 0 | I32: 0 | J32: 0 | K32: 0 | L32: 0 | M32: 0 | N32: 0 | O32: 0 | P32: 0 | Q32: 0 | R32: 0 | S32: 0 | T32: 0 | U32: 37.647059 | V32: 23.529412 | W32: 18.823529 | X32: 18.823529 | Y32: 18.823529 | Z32: 18.823529 | AA32: 23.529412 | AB32: 61.176471 | AC32: 94.117647 | AD32: 51.764706 | AE32: 51.764706 | AF32: 51.764706
A33: Pass | B33: 37.647059 | C33: 37.647059 | D33: 37.647059 | E33: 65.882353 | F33: 23.529412 | G33: 65.882353 | H33: 84.705882 | I33: 18.823529 | J33: 18.823529 | K33: 18.823529 | L33: 18.823529 | M33: 18.823529 | N33: 37.647059 | O33: 47.058824 | P33: 14.117647 | Q33: 14.117647 | R33: 14.117647 | S33: 14.117647 | T33: 14.117647 | U33: 37.647059 | V33: 56.470588 | W33: 9.4117647 | X33: 9.4117647 | Y33: 9.4117647 | Z33: 9.4117647 | AA33: 9.4117647 | AB33: 56.470588 | AC33: 65.882353 | AD33: 37.647059 | AE33: 37.647059 | AF33: 41.411765
A34: TA + Cong | B34: 0 | C34: 0 | D34: 0 | E34: 0 | F34: 16 | G34: 0 | H34: 0 | I34: 0 | J34: 263.52941 | K34: 188.23529 | L34: 0 | M34: 0 | N34: 0 | O34: 18.823529 | P34: 258.82353 | Q34: 0 | R34: 0 | S34: 0 | T34: 0 | U34: 169.41176 | V34: 0 | W34: 0 | X34: 0 | Y34: 0 | Z34: 56.470588 | AA34: 56.470588 | AB34: 0 | AC34: 0 | AD34: 282.35294 | AE34: 1694.1176 | AF34: 282.35294
A35: Invités | B35: 37.647059 | C35: 564.70588 | D35: 18.823529 | E35: 56.470588 | F35: 470.58824 | G35: 70.588235 | H35: 47.058824 | I35: 47.058824 | J35: 42.352941 | K35: 4.7058824 | L35: 56.470588 | M35: 37.647059 | N35: 329.41176 | O35: 65.882353 | P35: 9.4117647 | Q35: 47.058824 | R35: 141.17647 | S35: 37.647059 | T35: 18.823529 | U35: 141.17647 | V35: 160 | W35: 47.058824 | X35: 28.235294 | Y35: 65.882353 | Z35: 47.058824 | AA35: 84.705882 | AB35: 263.52941 | AC35: 188.23529 | AD35: 47.058824 | AE35: 320 | AF35: 65.882353
B37: 40269 | C37: 40270 | D37: 40271 | E37: 40272 | F37: 40273 | G37: 40274 | H37: 40275 | I37: 40276 | J37: 40277 | K37: 40278 | L37: 40279 | M37: 40280 | N37: 40281 | O37: 40282 | P37: 40283 | Q37: 40284 | R37: 40285 | S37: 40286 | T37: 40287 | U37: 40288 | V37: 40289 | W37: 40290 | X37: 40291 | Y37: 40292 | Z37: 40293 | AA37: 40294 | AB37: 40295 | AC37: 40296 | AD37: 40297 | AE37: 40298
A38: Ind Cash | B38: 333.17647 | C38: 319.10588 | D38: 2330.5412 | E38: 1768.3765 | F38: 2289.7882 | G38: 1888.9412 | H38: 1774.5412 | I38: 1827.2471 | J38: 3002.5412 | K38: 2300.1412 | L38: 1561.8824 | M38: 1616.2353 | N38: 3166.4 | O38: 3391.5294 | P38: 3326.5882 | Q38: 2179.9059 | R38: 2674.0706 | S38: 1909.7412 | T38: 2258.6353 | U38: 2875.1529 | V38: 2772.1412 | W38: 2986.9647 | X38: 2053.6471 | Y38: 2673.7412 | Z38: 3879.4353 | AA38: 884.42353 | AB38: 985.83529 | AC38: 946.58824 | AD38: 859.29412 | AE38: 699.29412
A39: Ind Résa | B39: 482.82353 | C39: 595.71765 | D39: 2091.1059 | E39: 2375.6235 | F39: 2427.3882 | G39: 3361.8824 | H39: 3275.8118 | I39: 3396.2824 | J39: 2839.3412 | K39: 3374.2118 | L39: 4933.1765 | M39: 4665.1765 | N39: 5301.3647 | O39: 5359.5294 | P39: 5104.4706 | Q39: 3617.7412 | R39: 3118.8706 | S39: 3017.3176 | T39: 4364.4235 | U39: 6050.0235 | V39: 5756.8 | W39: 5927.8588 | X39: 3472.9412 | Y39: 3214.2588 | Z39: 2475.3882 | AA39: 2046.4 | AB39: 2541.6941 | AC39: 2207.2941 | AD39: 1777.8824 | AE39: 1542.5882
A41: G. AD | B41: 45.176471 | C41: 16.941176 | D41: 1665.8824 | E41: 1232 | F41: 80.941176 | G41: 45.176471 | H41: 36.705882 | I41: 268.23529 | J41: 263.52941 | K41: 920.47059 | L41: 1127.5294 | M41: 238.11765 | N41: 75.294118 | O41: 114.82353 | P41: 103.52941 | Q41: 0 | R41: 847.05882 | S41: 724.70588 | T41: 33.882353 | U41: 133.64706 | V41: 109.17647 | W41: 150.58824 | X41: 164.70588 | Y41: 1763.7647 | Z41: 1421.1765 | AA41: 73.411765 | AB41: 113.88235 | AC41: 110.11765 | AD41: 59.294118 | AE41: 240
A42: G Jeune | B42: 1750.5882 | C42: 3512.4706 | D42: 2964.7059 | E42: 729.41176 | F42: 456.47059 | G42: 1111.5294 | H42: 1294.1176 | I42: 970.35294 | J42: 1031.5294 | K42: 1063.5294 | L42: 377.41176 | M42: 131.76471 | N42: 178.82353 | O42: 991.05882 | P42: 971.29412 | Q42: 1400.4706 | R42: 927.05882 | S42: 348.23529 | T42: 190.11765 | U42: 219.29412 | V42: 688.94118 | W42: 1066.3529 | X42: 1472.9412 | Y42: 1488.9412 | Z42: 155.29412 | AA42: 151.52941 | AB42: 469.64706 | AC42: 1225.4118 | AD42: 1548.2353 | AE42: 1228.2353
A44: Nocturne | B44: 51.764706 | C44: 51.764706 | D44: 160 | E44: 254.11765 | F44: 141.17647 | G44: 141.17647 | H44: 103.52941 | I44: 112.94118 | J44: 103.52941 | K44: 94.117647 | L44: 70.588235 | M44: 75.294118 | N44: 94.117647 | O44: 94.117647 | P44: 70.588235 | Q44: 70.588235 | R44: 75.294118 | S44: 47.058824 | T44: 47.058824 | U44: 75.294118 | V44: 56.470588 | W44: 94.117647 | X44: 70.588235 | Y44: 141.17647 | Z44: 131.76471 | AA44: 84.705882 | AB44: 37.647059 | AC44: 37.647059 | AD44: 37.647059 | AE44: 37.647059
A45: Pass | B45: 37.647059 | C45: 37.647059 | D45: 37.647059 | E45: 65.882353 | F45: 65.882353 | G45: 56.470588 | H45: 47.058824 | I45: 47.058824 | J45: 47.058824 | K45: 51.764706 | L45: 112.94118 | M45: 70.588235 | N45: 65.882353 | O45: 65.882353 | P45: 65.882353 | Q45: 47.058824 | R45: 37.647059 | S45: 47.058824 | T45: 47.058824 | U45: 47.058824 | V45: 47.058824 | W45: 47.058824 | X45: 47.058824 | Y45: 47.058824 | Z45: 70.588235 | AA45: 94.117647 | AB45: 291.76471 | AC45: 18.823529 | AD45: 18.823529 | AE45: 18.823529
A46: TA + Cong | B46: 0 | C46: 0 | D46: 0 | E46: 0 | F46: 141.17647 | G46: 0 | H46: 0 | I46: 244.70588 | J46: 47.058824 | K46: 235.29412 | L46: 0 | M46: 0 | N46: 0 | O46: 0 | P46: 0 | Q46: 0 | R46: 141.17647 | S46: 0 | T46: 0 | U46: 0 | V46: 0 | W46: 0 | X46: 0 | Y46: 0 | Z46: 0 | AA46: 0 | AB46: 28.235294 | AC46: 28.235294 | AD46: 564.70588 | AE46: 0
A47: Invités | B47: 84.705882 | C47: 188.23529 | D47: 352.94118 | E47: 211.76471 | F47: 94.117647 | G47: 94.117647 | H47: 65.882353 | I47: 94.117647 | J47: 122.35294 | K47: 169.41176 | L47: 244.70588 | M47: 169.41176 | N47: 301.17647 | O47: 141.17647 | P47: 94.117647 | Q47: 174.11765 | R47: 141.17647 | S47: 65.882353 | T47: 112.94118 | U47: 103.52941 | V47: 94.117647 | W47: 117.64706 | X47: 84.705882 | Y47: 211.76471 | Z47: 122.35294 | AA47: 84.705882 | AB47: 108.23529 | AC47: 94.117647 | AD47: 84.705882 | AE47: 211.76471
B49: 40299 | C49: 40300 | D49: 40301 | E49: 40302 | F49: 40303 | G49: 40304 | H49: 40305 | I49: 40306 | J49: 40307 | K49: 40308 | L49: 40309 | M49: 40310 | N49: 40311 | O49: 40312 | P49: 40313 | Q49: 40314 | R49: 40315 | S49: 40316 | T49: 40317 | U49: 40318 | V49: 40319 | W49: 40320 | X49: 40321 | Y49: 40322 | Z49: 40323 | AA49: 40324 | AB49: 40325 | AC49: 40326 | AD49: 40327 | AE49: 40328 | AF49: 40329
A50: Ind Cash | B50: 3040.7059 | C50: 1348.2353 | D50: 275.48235 | E50: 303.48235 | F50: 318.30588 | G50: 365.17647 | H50: 441.12941 | I50: 3758.4 | J50: 2567.4824 | K50: 322.49412 | L50: 348.18824 | M50: 289.31765 | N50: 817.08235 | O50: 1056 | P50: 2220.2824 | Q50: 1263.5294 | R50: 370.49412 | S50: 387.15294 | T50: 415.57647 | U50: 457.41176 | V50: 818.77647 | W50: 2877.5059 | X50: 1740.2353 | Y50: 600.75294 | Z50: 503.05882 | AA50: 410.58824 | AB50: 366.82353 | AC50: 338.96471 | AD50: 3256 | AE50: 3201.9294 | AF50: 1101.8353
A51: Ind Résa | B51: 2803.0588 | C51: 1125.1765 | D51: 766.4 | E51: 993.45882 | F51: 784.75294 | G51: 783.05882 | H51: 3392.2824 | I51: 5859.4824 | J51: 1940.7529 | K51: 529.27059 | L51: 639.10588 | M51: 581.27059 | N51: 572.09412 | O51: 581.64706 | P51: 1965.1294 | Q51: 1271.0588 | R51: 722.21176 | S51: 874.96471 | T51: 887.01176 | U51: 3056.9412 | V51: 6295.5765 | W51: 5147.9059 | X51: 1693.1765 | Y51: 570.07059 | Z51: 707.29412 | AA51: 677.41176 | AB51: 605.41176 | AC51: 557.03529 | AD51: 2815.5294 | AE51: 4657.8353 | AF51: 1387.5765
A53: G. AD | B53: 2715.2941 | C53: 1658.3529 | D53: 72.470588 | E53: 0 | F53: 0 | G53: 36.705882 | H53: 179.76471 | I53: 2649.4118 | J53: 1616.9412 | K53: 0 | L53: 0 | M53: 0 | N53: 294.58824 | O53: 569.41176 | P53: 2936.4706 | Q53: 1906.8235 | R53: 32.941176 | S53: 34.823529 | T53: 0 | U53: 144 | V53: 2043.2941 | W53: 3532.2353 | X53: 814.11765 | Y53: 97.882353 | Z53: 208.94118 | AA53: 217.41176 | AB53: 176 | AC53: 95.058824 | AD53: 239.05882 | AE53: 1514.3529 | AF53: 812.23529
...

Sheet 6 - 1,6M visite 181109
K2: France | AA2: International
B3: Budget 2010 | C3: Mois | D3: Jour | E3: Date | F3: Sem | G3: JF | H3: VAC | K3: Ind Cash | N3: Ind Rés | Z3: Ind total | AA3: Ind Cash | AD3: Ind Rés | AP3: Ind total | AQ3: % Ind Rés / Total Ind Brut | AR3: Total cash | AS3: Total résa | AT3: Ind Brut | AU3: Nocturne | AV3: Pass | AW3: TA CONG | AX3: Invités | AY3: Total Divers | BA3: G Adulte | BF3: G J | BG3: Total Groupe | BH3: Total | BI3: Cumul | FE3: Dates | FF3: Indiv cash | FG3: Indiv résa | FH3: Total Individuels | FI3: Grpes Adultes | FJ3: Grpes Jeunes | FK3: Total Groupes | FL3: Nocturnes | FM3: Pass | FN3: Tourisme d'Affaires | FO3: Invités | FP3: Total Divers | FR3: Fréquentat° Totale | FT3: Indiv | FU3: Groupe | FV3: Prévi Fréq hors TA CONGRES | FW3: Delta = TA + Congrés
L4: Sec | M4: France | AB4: Sec | AC4: International | BA4: France | BC4: Total
K5: 1 Jour | L5: 2 Jours & + | M5: Total | N5: 1 jour | O5: 2 Jours & + | P5: Total | Q5: 1 jour | R5: 2 Jours & + | S5: Total | T5: 1 jour | U5: 2 Jours & + | V5: Total | W5: 1 jour | X5: 2 Jours & + | Y5: Total | AA5: 1 Jour | AB5: 2 Jours & + | AC5: Total | AD5: 1 jour | AE5: 2 Jours & + | AF5: Total | AG5: 1 jour | AH5: 2 Jours & + | AI5: Total | AJ5: 1 jour | AK5: 2 Jours & + | AL5: Total | AM5: 1 jour | AN5: 2 Jours & + | AO5: Total | BA5: 1 jour | BB5: 2 Jours & + | BC5: 1 jour | BD5: 2 Jours & + | BE5: Total | BF5: Total
A6: 0 | B6: 40179 | C6: 40179 | D6: 39451 | E6: 40179 | F6: 0 | G6: Jour An | H6: ABC | K6: 1536 | L6: 155.29412 | M6: 1691.2941 | N6: 425.41176 | O6: 153.41176 | P6: 578.82353 | Q6: 53.647059 | R6: 7.5294118 | S6: 61.176471 | T6: 321.88235 | U6: 2870.5882 | V6: 3192.4706 | W6: 800.94118 | X6: 3031.5294 | Y6: 3832.4706 | Z6: 5523.7647 | AA6: 19.2 | AB6: 5.9294118 | AC6: 25.129412 | AD6: 0 | AE6: 0 | AF6: 0 | AG6: 44.8 | AH6: 13.835294 | AI6: 58.635294 | AJ6: 20.705882 | AK6: 104.47059 | AL6: 125.17647 | AM6: 65.505882 | AN6: 118.30588 | AO6: 183.81176 | AP6: 208.94118 | AQ6: 0 | AR6: 1716.4235 | AS6: 4016.2824 | AT6: 5732.7059 | AU6: 0 | AV6: 112.94118 | AW6: 16 | AX6: 635.29412 | AY6: 764.23529 | AZ6: 0 | BA6: 0 | BB6: 0 | BC6: 0 | BD6: 0 | BE6: 0 | BF6: 0 | BG6: 0 | BH6: 6496.9412 | BI6: 6496.9412 | FE6: 40179 | FF6: 1536 | FG6: 425.41176 | FH6: 1961.4118 | FI6: 0 | FJ6: #REF! | FK6: #REF! | FL6: 0 | FM6: 112.94118 | FN6: #REF! | FO6: 635.29412 | FP6: #REF! | FR6: #REF!
A7: 0 | B7: 40180 | C7: 40180 | D7: 39452 | E7: 40180 | F7: 0 | H7: ABC | K7: 1668.7059 | L7: 290.82353 | M7: 1959.5294 | N7: 363.29412 | O7: 119.52941 | P7: 482.82353 | Q7: 50.823529 | R7: 7.5294118 | S7: 58.352941 | T7: 336.94118 | U7: 2881.8824 | V7: 3218.8235 | W7: 751.05882 | X7: 3008.9412 | Y7: 3760 | Z7: 5719.5294 | AA7: 15.529412 | AB7: 6.4941176 | AC7: 22.023529 | AD7: 0 | AE7: 0 | AF7: 0 | AG7: 36.235294 | AH7: 15.152941 | AI7: 51.388235 | AJ7: 42.352941 | AK7: 151.52941 | AL7: 193.88235 | AM7: 78.588235 | AN7: 166.68235 | AO7: 245.27059 | AP7: 267.29412 | AQ7: 0 | AR7: 1981.5529 | AS7: 4005.2706 | AT7: 5986.8235 | AU7: 18.823529 | AV7: 112.94118 | AW7: 94.117647 | AX7: 658.82353 | AY7: 884.70588 | AZ7: 0 | BA7: 0 | BB7: 0 | BC7: 0 | BD7: 0 | BE7: 0 | BF7: 0 | BG7: 0 | BH7: 6871.5294 | BI7: 13368.471 | FE7: 40180 | FF7: 1668.7059 | FG7: 363.29412 | FH7: 2032 | FI7: 0 | FJ7: #REF! | FK7: #REF! | FL7: 18.823529 | FM7: 112.94118 | FN7: #REF! | FO7: 658.82353 | FP7: #REF! | FR7: #REF!
A8: 0 | B8: 40181 | C8: 40181 | D8: 39453 | E8: 40181 | F8: 0 | H8: ABC | K8: 847.05882 | L8: 70.588235 | M8: 917.64706 | N8: 136.47059 | O8: 58.352941 | P8: 194.82353 | Q8: 6.5882353 | R8: 0 | S8: 6.5882353 | T8: 102.58824 | U8: 862.11765 | V8: 964.70588 | W8: 245.64706 | X8: 920.47059 | Y8: 1166.1176 | Z8: 2083.7647 | AA8: 9.3176471 | AB8: 0 | AC8: 9.3176471 | AD8: 1.8823529 | AE8: 0 | AF8: 1.8823529 | AG8: 21.741176 | AH8: 0 | AI8: 21.741176 | AJ8: 19.764706 | AK8: 70.588235 | AL8: 90.352941 | AM8: 43.388235 | AN8: 70.588235 | AO8: 113.97647 | AP8: 123.29412 | AQ8: 0 | AR8: 926.96471 | AS8: 1280.0941 | AT8: 2207.0588 | AU8: 18.823529 | AV8: 112.94118 | AW8: 541.17647 | AX8: 357.64706 | AY8: 1030.5882 | AZ8: 0 | BA8: 0 | BB8: 0 | BC8: 0 | BD8: 0 | BE8: 0 | BF8: 0 | BG8: 0 | BH8: 3237.6471 | BI8: 16606.118 | FE8: 40181 | FF8: 847.05882 | FG8: 136.47059 | FH8: 983.52941 | FI8: 0 | FJ8: #REF! | FK8: #REF! | FL8: 18.823529 | FM8: 112.94118 | FN8: #REF! | FO8: 357.64706 | FP8: #REF! | FR8: #REF!
A9: 0 | B9: 40182 | C9: 40182 | D9: 39454 | E9: 40182 | F9: 1 | K9: 0 | L9: 0 | M9: 0 | N9: 0 | O9: 0 | P9: 0 | Q9: 0 | R9: 0 | S9: 0 | T9: 0 | U9: 0 | V9: 0 | W9: 0 | X9: 0 | Y9: 0 | Z9: 0 | AA9: 0 | AB9: 0 | AC9: 0 | AD9: 0 | AE9: 0 | AF9: 0 | AG9: 0 | AH9: 0 | AI9: 0 | AJ9: 0 | AK9: 0 | AL9: 0 | AM9: 0 | AN9: 0 | AO9: 0 | AP9: 0 | AQ9: 0 | AR9: 0 | AS9: 0 | AT9: 0 | AU9: 0 | AV9: 0 | AW9: 0 | AX9: 0 | AY9: 0 | AZ9: 0 | BA9: 0 | BB9: 0 | BC9: 0 | BD9: 0 | BE9: 0 | BF9: 0 | BG9: 0 | BH9: 0 | BI9: 16606.118 | FE9: 40182 | FF9: 0 | FG9: 0 | FH9: 0 | FI9: 0 | FJ9: #REF! | FK9: #REF! | FL9: 0 | FM9: 0 | FN9: #REF! | FO9: 0 | FP9: #REF! | FR9: #REF!
A10: 0 | B10: 40183 | C10: 40183 | D10: 39455 | E10: 40183 | F10: 1 | K10: 0 | L10: 0 | M10: 0 | N10: 0 | O10: 0 | P10: 0 | Q10: 0 | R10: 0 | S10: 0 | T10: 0 | U10: 0 | V10: 0 | W10: 0 | X10: 0 | Y10: 0 | Z10: 0 | AA10: 0 | AB10: 0 | AC10: 0 | AD10: 0 | AE10: 0 | AF10: 0 | AG10: 0 | AH10: 0 | AI10: 0 | AJ10: 0 | AK10: 0 | AL10: 0 | AM10: 0 | AN10: 0 | AO10: 0 | AP10: 0 | AQ10: 0 | AR10: 0 | AS10: 0 | AT10: 0 | AU10: 0 | AV10: 0 | AW10: 658.82353 | AX10: 0 | AY10: 658.82353 | AZ10: 0 | BA10: 0 | BB10: 0 | BC10: 0 | BD10: 0 | BE10: 0 | BF10: 0 | BG10: 0 | BH10: 658.82353 | BI10: 17264.941 | FE10: 40183 | FF10: 0 | FG10: 0 | FH10: 0 | FI10: 0 | FJ10: #REF! | FK10: #REF! | FL10: 0 | FM10: 0 | FN10: #REF! | FO10: 0 | FP10: #REF! | FR10: #REF!
A11: 0 | B11: 40184 | C11: 40184 | D11: 39456 | E11: 40184 | F11: 1 | K11: 0 | L11: 0 | M11: 0 | N11: 0 | O11: 0 | P11: 0 | Q11: 0 | R11: 0 | S11: 0 | T11: 0 | U11: 0 | V11: 0 | W11: 0 | X11: 0 | Y11: 0 | Z11: 0 | AA11: 0 | AB11: 0 | AC11: 0 | AD11: 0 | AE11: 0 | AF11: 0 | AG11: 0 | AH11: 0 | AI11: 0 | AJ11: 0 | AK11: 0 | AL11: 0 | AM11: 0 | AN11: 0 | AO11: 0 | AP11: 0 | AQ11: 0 | AR11: 0 | AS11: 0 | AT11: 0 | AU11: 0 | AV11: 0 | AW11: 0 | AX11: 0 | AY11: 0 | AZ11: 0 | BA11: 0 | BB11: 0 | BC11: 0 | BD11: 0 | BE11: 0 | BF11: 0 | BG11: 0 | BH11: 0 | BI11: 17264.941 | FE11: 40184 | FF11: 0 | FG11: 0 | FH11: 0 | FI11: 0 | FJ11: #REF! | FK11: #REF! | FL11: 0 | FM11: 0 | FN11: #REF! | FO11: 0 | FP11: #REF! | FR11: #REF!
A12: 0 | B12: 40185 | C12: 40185 | D12: 39457 | E12: 40185 | F12: 1 | K12: 0 | L12: 0 | M12: 0 | N12: 0 | O12: 0 | P12: 0 | Q12: 0 | R12: 0 | S12: 0 | T12: 0 | U12: 0 | V12: 0 | W12: 0 | X12: 0 | Y12: 0 | Z12: 0 | AA12: 0 | AB12: 0 | AC12: 0 | AD12: 0 | AE12: 0 | AF12: 0 | AG12: 0 | AH12: 0 | AI12: 0 | AJ12: 0 | AK12: 0 | AL12: 0 | AM12: 0 | AN12: 0 | AO12: 0 | AP12: 0 | AQ12: 0 | AR12: 0 | AS12: 0 | AT12: 0 | AU12: 0 | AV12: 0 | AW12: 188.23529 | AX12: 0 | AY12: 188.23529 | AZ12: 0 | BA12: 0 | BB12: 0 | BC12: 0 | BD12: 0 | BE12: 0 | BF12: 0 | BG12: 0 | BH12: 188.23529 | BI12: 17453.176 | FE12: 40185 | FF12: 0 | FG12: 0 | FH12: 0 | FI12: 0 | FJ12: #REF! | FK12: #REF! | FL12: 0 | FM12: 0 | FN12: #REF! | FO12: 0 | FP12: #REF! | FR12: #REF!
A13: 0 | B13: 40186 | C13: 40186 | D13: 39458 | E13: 40186 | F13: 1 | K13: 0 | L13: 0 | M13: 0 | N13: 0 | O13: 0 | P13: 0 | Q13: 0 | R13: 0 | S13: 0 | T13: 0 | U13: 0 | V13: 0 | W13: 0 | X13: 0 | Y13: 0 | Z13: 0 | AA13: 0 | AB13: 0 | AC13: 0 | AD13: 0 | AE13: 0 | AF13: 0 | AG13: 0 | AH13: 0 | AI13: 0 | AJ13: 0 | AK13: 0 | AL13: 0 | AM13: 0 | AN13: 0 | AO13: 0 | AP13: 0 | AQ13: 0 | AR13: 0 | AS13: 0 | AT13: 0 | AU13: 0 | AV13: 0 | AW13: 0 | AX13: 0 | AY13: 0 | AZ13: 0 | BA13: 0 | BB13: 0 | BC13: 0 | BD13: 0 | BE13: 0 | BF13: 0 | BG13: 0 | BH13: 0 | BI13: 17453.176 | FE13: 40186 | FF13: 0 | FG13: 0 | FH13: 0 | FI13: 0 | FJ13: #REF! | FK13: #REF! | FL13: 0 | FM13: 0 | FN13: #REF! | FO13: 0 | FP13: #REF! | FR13: #REF!
A14: 0 | B14: 40187 | C14: 40187 | D14: 39459 | E14: 40187 | F14: 1 | K14: 0 | L14: 0 | M14: 0 | N14: 0 | O14: 0 | P14: 0 | Q14: 0 | R14: 0 | S14: 0 | T14: 0 | U14: 0 | V14: 0 | W14: 0 | X14: 0 | Y14: 0 | Z14: 0 | AA14: 0 | AB14: 0 | AC14: 0 | AD14: 0 | AE14: 0 | AF14: 0 | AG14: 0 | AH14: 0 | AI14: 0 | AJ14: 0 | AK14: 0 | AL14: 0 | AM14: 0 | AN14: 0 | AO14: 0 | AP14: 0 | AQ14: 0 | AR14: 0 | AS14: 0 | AT14: 0 | AU14: 0 | AV14: 0 | AW14: 21.647059 | AX14: 0 | AY14: 21.647059 | AZ14: 0 | BA14: 0 | BB14: 0 | BC14: 0 | BD14: 0 | BE14: 0 | BF14: 0 | BG14: 0 | BH14: 21.647059 | BI14: 17474.824 | FE14: 40187 | FF14: 0 | FG14: 0 | FH14: 0 | FI14: 0 | FJ14: #REF! | FK14: #REF! | FL14: 0 | FM14: 0 | FN14: #REF! | FO14: 0 | FP14: #REF! | FR14: #REF!
A15: 0 | B15: 40188 | C15: 40188 | D15: 39460 | E15: 40188 | F15: 1 | K15: 0 | L15: 0 | M15: 0 | N15: 0 | O15: 0 | P15: 0 | Q15: 0 | R15: 0 | S15: 0 | T15: 0 | U15: 0 | V15: 0 | W15: 0 | X15: 0 | Y15: 0 | Z15: 0 | AA15: 0 | AB15: 0 | AC15: 0 | AD15: 0 | AE15: 0 | AF15: 0 | AG15: 0 | AH15: 0 | AI15: 0 | AJ15: 0 | AK15: 0 | AL15: 0 | AM15: 0 | AN15: 0 | AO15: 0 | AP15: 0 | AQ15: 0 | AR15: 0 | AS15: 0 | AT15: 0 | AU15: 0 | AV15: 0 | AW15: 0 | AX15: 0 | AY15: 0 | AZ15: 0 | BA15: 0 | BB15: 0 | BC15: 0 | BD15: 0 | BE15: 0 | BF15: 0 | BG15: 0 | BH15: 0 | BI15: 17474.824 | FE15: 40188 | FF15: 0 | FG15: 0 | FH15: 0 | FI15: 0 | FJ15: #REF! | FK15: #REF! | FL15: 0 | FM15: 0 | FN15: #REF! | FO15: 0 | FP15: #REF! | FR15: #REF!
A16: 0 | B16: 40189 | C16: 40189 | D16: 39461 | E16: 40189 | F16: 2 | K16: 0 | L16: 0 | M16: 0 | N16: 0 | O16: 0 | P16: 0 | Q16: 0 | R16: 0 | S16: 0 | T16: 0 | U16: 0 | V16: 0 | W16: 0 | X16: 0 | Y16: 0 | Z16: 0 | AA16: 0 | AB16: 0 | AC16: 0 | AD16: 0 | AE16: 0 | AF16: 0 | AG16: 0 | AH16: 0 | AI16: 0 | AJ16: 0 | AK16: 0 | AL16: 0 | AM16: 0 | AN16: 0 | AO16: 0 | AP16: 0 | AQ16: 0 | AR16: 0 | AS16: 0 | AT16: 0 | AU16: 0 | AV16: 0 | AW16: 0 | AX16: 0 | AY16: 0 | AZ16: 0 | BA16: 0 | BB16: 0 | BC16: 0 | BD16: 0 | BE16: 0 | BF16: 0 | BG16: 0 | BH16: 0 | BI16: 17474.824 | FE16: 40189 | FF16: 0 | FG16: 0 | FH16: 0 | FI16: 0 | FJ16: #REF! | FK16: #REF! | FL16: 0 | FM16: 0 | FN16: #REF! | FO16: 0 | FP16: #REF! | FR16: #REF!
A17: 0 | B17: 40190 | C17: 40190 | D17: 39462 | E17: 40190 | F17: 2 | K17: 0 | L17: 0 | M17: 0 | N17: 0 | O17: 0 | P17: 0 | Q17: 0 | R17: 0 | S17: 0 | T17: 0 | U17: 0 | V17: 0 | W17: 0 | X17: 0 | Y17: 0 | Z17: 0 | AA17: 0 | AB17: 0 | AC17: 0 | AD17: 0 | AE17: 0 | AF17: 0 | AG17: 0 | AH17: 0 | AI17: 0 | AJ17: 0 | AK17: 0 | AL17: 0 | AM17: 0 | AN17: 0 | AO17: 0 | AP17: 0 | AQ17: 0 | AR17: 0 | AS17: 0 | AT17: 0 | AU17: 0 | AV17: 0 | AW17: 0 | AX17: 0 | AY17: 0 | AZ17: 0 | BA17: 0 | BB17: 0 | BC17: 0 | BD17: 0 | BE17: 0 | BF17: 0 | BG17: 0 | BH17: 0 | BI17: 17474.824 | FE17: 40190 | FF17: 0 | FG17: 0 | FH17: 0 | FI17: 0 | FJ17: #REF! | FK17: #REF! | FL17: 0 | FM17: 0 | FN17: #REF! | FO17: 0 | FP17: #REF! | FR17: #REF!
A18: 0 | B18: 40191 | C18: 40191 | D18: 39463 | E18: 40191 | F18: 2 | K18: 0 | L18: 0 | M18: 0 | N18: 0 | O18: 0 | P18: 0 | Q18: 0 | R18: 0 | S18: 0 | T18: 0 | U18: 0 | V18: 0 | W18: 0 | X18: 0 | Y18: 0 | Z18: 0 | AA18: 0 | AB18: 0 | AC18: 0 | AD18: 0 | AE18: 0 | AF18: 0 | AG18: 0 | AH18: 0 | AI18: 0 | AJ18: 0 | AK18: 0 | AL18: 0 | AM18: 0 | AN18: 0 | AO18: 0 | AP18: 0 | AQ18: 0 | AR18: 0 | AS18: 0 | AT18: 0 | AU18: 0 | AV18: 0 | AW18: 0 | AX18: 0 | AY18: 0 | AZ18: 0 | BA18: 0 | BB18: 0 | BC18: 0 | BD18: 0 | BE18: 0 | BF18: 0 | BG18: 0 | BH18: 0 | BI18: 17474.824 | FE18: 40191 | FF18: 0 | FG18: 0 | FH18: 0 | FI18: 0 | FJ18: #REF! | FK18: #REF! | FL18: 0 | FM18: 0 | FN18: #REF! | FO18: 0 | FP18: #REF! | FR18: #REF!
A19: 0 | B19: 40192 | C19: 40192 | D19: 39464 | E19: 40192 | F19: 2 | K19: 0 | L19: 0 | M19: 0 | N19: 0 | O19: 0 | P19: 0 | Q19: 0 | R19: 0 | S19: 0 | T19: 0 | U19: 0 | V19: 0 | W19: 0 | X19: 0 | Y19: 0 | Z19: 0 | AA19: 0 | AB19: 0 | AC19: 0 | AD19: 0 | AE19: 0 | AF19: 0 | AG19: 0 | AH19: 0 | AI19: 0 | AJ19: 0 | AK19: 0 | AL19: 0 | AM19: 0 | AN19: 0 | AO19: 0 | AP19: 0 | AQ19: 0 | AR19: 0 | AS19: 0 | AT19: 0 | AU19: 0 | AV19: 0 | AW19: 322.82353 | AX19: 0 | AY19: 322.82353 | AZ19: 0 | BA19: 0 | BB19: 0 | BC19: 0 | BD19: 0 | BE19: 0 | BF19: 0 | BG19: 0 | BH19: 322.82353 | BI19: 17797.647 | FE19: 40192 | FF19: 0 | FG19: 0 | FH19: 0 | FI19: 0 | FJ19: #REF! | FK19: #REF! | FL19: 0 | FM19: 0 | FN19: #REF! | FO19: 0 | FP19: #REF! | FR19: #REF!
A20: 0 | B20: 40193 | C20: 40193 | D20: 39465 | E20: 40193 | F20: 2 | K20: 0 | L20: 0 | M20: 0 | N20: 0 | O20: 0 | P20: 0 | Q20: 0 | R20: 0 | S20: 0 | T20: 0 | U20: 0 | V20: 0 | W20: 0 | X20: 0 | Y20: 0 | Z20: 0 | AA20: 0 | AB20: 0 | AC20: 0 | AD20: 0 | AE20: 0 | AF20: 0 | AG20: 0 | AH20: 0 | AI20: 0 | AJ20: 0 | AK20: 0 | AL20: 0 | AM20: 0 | AN20: 0 | AO20: 0 | AP20: 0 | AQ20: 0 | AR20: 0 | AS20: 0 | AT20: 0 | AU20: 0 | AV20: 0 | AW20: 59.294118 | AX20: 0 | AY20: 59.294118 | AZ20: 0 | BA20: 0 | BB20: 0 | BC20: 0 | BD20: 0 | BE20: 0 | BF20: 0 | BG20: 0 | BH20: 59.294118 | BI20: 17856.941 | FE20: 40193 | FF20: 0 | FG20: 0 | FH20: 0 | FI20: 0 | FJ20: #REF! | FK20: #REF! | FL20: 0 | FM20: 0 | FN20: #REF! | FO20: 0 | FP20: #REF! | FR20: #REF!
... A36: 0 | B36: 40209 | C36: 40209 | D36: 39481 | E36: 40209 | F36: 4 | K36: 0 | L36: 0 | M36: 0 | N36: 0 | O36: 0 | P36: 0 | Q36: 0 | R36: 0 | S36: 0 | T36: 0 | U36: 0 | V36: 0 | W36: 0 | X36: 0 | Y36: 0 | Z36: 0 | AA36: 0 | AB36: 0 | AC36: 0 | AD36: 0 | AE36: 0 | AF36: 0 | AG36: 0 | AH36: 0 | AI36: 0 | AJ36: 0 | AK36: 0 | AL36: 0 | AM36: 0 | AN36: 0 | AO36: 0 | AP36: 0 | AQ36: 0 | AR36: 0 | AS36: 0 | AT36: 0 | AU36: 0 | AV36: 0 | AW36: 376.47059 | AX36: 0 | AY36: 376.47059 | AZ36: 0 | BA36: 0 | BB36: 0 | BC36: 0 | BD36: 0 | BE36: 0 | BF36: 0 | BG36: 0 | BH36: 376.47059 | BI36: 20118.588 | FE36: 40209 | FF36: 0 | FG36: 0 | FH36: 0 | FI36: 0 | FJ36: #REF! | FK36: #REF! | FL36: 0 | FM36: 0 | FN36: #REF! | FO36: 0 | FP36: #REF! | FR36: #REF!
AT37: 0 | AY37: 0
A38: 0 | B38: 40210 | C38: 40210 | D38: 39482 | E38: 40210 | F38: 5 | K38: 0 | L38: 0 | M38: 0 | N38: 0 | O38: 0 | P38: 0 | Q38: 0 | R38: 0 | S38: 0 | T38: 0 | U38: 0 | V38: 0 | W38: 0 | X38: 0 | Y38: 0 | Z38: 0 | AA38: 0 | AB38: 0 | AC38: 0 | AD38: 0 | AE38: 0 | AF38: 0 | AG38: 0 | AH38: 0 | AI38: 0 | AJ38: 0 | AK38: 0 | AL38: 0 | AM38: 0 | AN38: 0 | AO38: 0 | AP38: 0 | AQ38: 0 | AR38: 0 | AS38: 0 | AT38: 0 | AU38: 0 | AV38: 0 | AW38: 0 | AX38: 0 | AY38: 0 | AZ38: 0 | BA38: 0 | BB38: 0 | BC38: 0 | BD38: 0 | BE38: 0 | BF38: 0 | BG38: 0 | BH38: 0 | BI38: 20118.588 | FE38: 40210 | FF38: 0 | FG38: 0 | FH38: 0 | FI38: 0 | FJ38: #REF! | FK38: #REF! | FL38: 0 | FM38: 0 | FN38: #REF! | FO38: 0 | FP38: #REF! | FR38: #REF!
A39: 0 | B39: 40211 | C39: 40211 | D39: 39483 | E39: 40211 | F39: 5 | K39: 0 | L39: 0 | M39: 0 | N39: 0 | O39: 0 | P39: 0 | Q39: 0 | R39: 0 | S39: 0 | T39: 0 | U39: 0 | V39: 0 | W39: 0 | X39: 0 | Y39: 0 | Z39: 0 | AA39: 0 | AB39: 0 | AC39: 0 | AD39: 0 | AE39: 0 | AF39: 0 | AG39: 0 | AH39: 0 | AI39: 0 | AJ39: 0 | AK39: 0 | AL39: 0 | AM39: 0 | AN39: 0 | AO39: 0 | AP39: 0 | AQ39: 0 | AR39: 0 | AS39: 0 | AT39: 0 | AU39: 0 | AV39: 0 | AW39: 0 | AX39: 0 | AY39: 0 | AZ39: 0 | BA39: 0 | BB39: 0 | BC39: 0 | BD39: 0 | BE39: 0 | BF39: 0 | BG39: 0 | BH39: 0 | BI39: 20118.588 | FE39: 40211 | FF39: 0 | FG39: 0 | FH39: 0 | FI39: 0 | FJ39: #REF! | FK39: #REF! | FL39: 0 | FM39: 0 | FN39: #REF! | FO39: 0 | FP39: #REF! | FR39: #REF!
A40: 0 | B40: 40212 | C40: 40212 | D40: 39484 | E40: 40212 | F40: 5 | K40: 0 | L40: 0 | M40: 0 | N40: 0 | O40: 0 | P40: 0 | Q40: 0 | R40: 0 | S40: 0 | T40: 0 | U40: 0 | V40: 0 | W40: 0 | X40: 0 | Y40: 0 | Z40: 0 | AA40: 0 | AB40: 0 | AC40: 0 | AD40: 0 | AE40: 0 | AF40: 0 | AG40: 0 | AH40: 0 | AI40: 0 | AJ40: 0 | AK40: 0 | AL40: 0 | AM40: 0 | AN40: 0 | AO40: 0 | AP40: 0 | AQ40: 0 | AR40: 0 | AS40: 0 | AT40: 0 | AU40: 0 | AV40: 0 | AW40: 0 | AX40: 0 | AY40: 0 | AZ40: 0 | BA40: 0 | BB40: 0 | BC40: 0 | BD40: 0 | BE40: 0 | BF40: 0 | BG40: 0 | BH40: 0 | BI40: 20118.588 | FE40: 40212 | FF40: 0 | FG40: 0 | FH40: 0 | FI40: 0 | FJ40: #REF! | FK40: #REF! | FL40: 0 | FM40: 0 | FN40: #REF! | FO40: 0 | FP40: #REF! | FR40: #REF!
A41: 0 | B41: 40213 | C41: 40213 | D41: 39485 | E41: 40213 | F41: 5 | K41: 0 | L41: 0 | M41: 0 | N41: 0 | O41: 0 | P41: 0 | Q41: 0 | R41: 0 | S41: 0 | T41: 0 | U41: 0 | V41: 0 | W41: 0 | X41: 0 | Y41: 0 | Z41: 0 | AA41: 0 | AB41: 0 | AC41: 0 | AD41: 0 | AE41: 0 | AF41: 0 | AG41: 0 | AH41: 0 | AI41: 0 | AJ41: 0 | AK41: 0 | AL41: 0 | AM41: 0 | AN41: 0 | AO41: 0 | AP41: 0 | AQ41: 0 | AR41: 0 | AS41: 0 | AT41: 0 | AU41: 0 | AV41: 0 | AW41: 235.29412 | AX41: 0 | AY41: 235.29412 | AZ41: 0 | BA41: 0 | BB41: 0 | BC41: 0 | BD41: 0 | BE41: 0 | BF41: 0 | BG41: 0 | BH41: 235.29412 | BI41: 20353.882 | FE41: 40213 | FF41: 0 | FG41: 0 | FH41: 0 | FI41: 0 | FJ41: #REF! | FK41: #REF! | FL41: 0 | FM41: 0 | FN41: #REF! | FO41: 0 | FP41: #REF! | FR41: #REF!
A42: 0 | B42: 40214 | C42: 40214 | D42: 39486 | E42: 40214 | F42: 5 | K42: 0 | L42: 0 | M42: 0 | N42: 0 | O42: 0 | P42: 0 | Q42: 0 | R42: 0 | S42: 0 | T42: 0 | U42: 0 | V42: 0 | W42: 0 | X42: 0 | Y42: 0 | Z42: 0 | AA42: 0 | AB42: 0 | AC42: 0 | AD42: 0 | AE42: 0 | AF42: 0 | AG42: 0 | AH42: 0 | AI42: 0 | AJ42: 0 | AK42: 0 | AL42: 0 | AM42: 0 | AN42: 0 | AO42: 0 | AP42: 0 | AQ42: 0 | AR42: 0 | AS42: 0 | AT42: 0 | AU42: 0 | AV42: 0 | AW42: 0 | AX42: 0 | AY42: 0 | AZ42: 0 | BA42: 0 | BB42: 0 | BC42: 0 | BD42: 0 | BE42: 0 | BF42: 0 | BG42: 0 | BH42: 0 | BI42: 20353.882 | FE42: 40214 | FF42: 0 | FG42: 0 | FH42: 0 | FI42: 0 | FJ42: #REF! | FK42: #REF! | FL42: 0 | FM42: 0 | FN42: #REF! | FO42: 0 | FP42: #REF! | FR42: #REF!
A43: 0 | B43: 40215 | C43: 40215 | D43: 39487 | E43: 40215 | F43: 5 | H43: B | K43: 1214.1176 | L43: 240 | M43: 1454.1176 | N43: 541.17647 | O43: 42.352941 | P43: 583.52941 | Q43: 2.8235294 | R43: 0 | S43: 2.8235294 | T43: 51.764706 | U43: 1101.1765 | V43: 1152.9412 | W43: 595.76471 | X43: 1143.5294 | Y43: 1739.2941 | Z43: 3193.4118 | AA43: 0 | AB43: 0 | AC43: 0 | AD43: 0 | AE43: 0 | AF43: 0 | AG43: 0 | AH43: 0 | AI43: 0 | AJ43: 0 | AK43: 0 | AL43: 0 | AM43: 0 | AN43: 0 | AO43: 0 | AP43: 0 | AQ43: 0 | AR43: 1454.1176 | AS43: 1739.2941 | AT43: 3193.4118 | AU43: 0 | AV43: 112.94118 | AW43: 11.294118 | AX43: 613 | AY43: 737.23529 | AZ43: 0 | BA43: 70.588235 | BB43: 82.823529 | BC43: 70.588235 | BD43: 82.823529 | BE43: 153.41176 | BF43: 0 | BG43: 153.41176 | BH43: 4084.0588 | BI43: 24437.941 | FE43: 40215 | FF43: 1214.1176 | FG43: 541.17647 | FH43: 1755.2941 | FI43: 70.588235 | FJ43: #REF! | FK43: #REF! | FL43: 0 | FM43: 112.94118 | FN43: #REF! | FO43: 613 | FP43: #REF! | FR43: #REF!
A44: 0 | B44: 40216 | C44: 40216 | D44: 39488 | E44: 40216 | F44: 5 | H44: B | K44: 729.41176 | L44: 230.58824 | M44: 960 | N44: 371.76471 | O44: 38.588235 | P44: 410.35294 | Q44: 13.176471 | R44: 0 | S44: 13.176471 | T44: 51.764706 | U44: 729.41176 | V44: 781.17647 | W44: 436.70588 | X44: 768 | Y44: 1204.7059 | Z44: 2164.7059 | AA44: 0.84705882 | AB44: 0 | AC44: 0.84705882 | AD44: 0 | AE44: 0 | AF44: 0 | AG44: 1.9764706 | AH44: 0 | AI44: 1.9764706 | AJ44: 0 | AK44: 13.176471 | AL44: 13.176471 | AM44: 1.9764706 | AN44: 13.176471 | AO44: 15.152941 | AP44: 16 | AQ44: 0 | AR44: 960.84706 | AS44: 1219.8588 | AT44: 2180.7059 | AU44: 0 | AV44: 141.17647 | AW44: 11.294118 | AX44: 37.647059 | AY44: 190.11765 | AZ44: 0 | BA44: 0 | BB44: 0 | BC44: 0 | BD44: 0 | BE44: 0 | BF44: 23.529412 | BG44: 23.529412 | BH44: 2394.3529 | BI44: 26832.294 | FE44: 40216 | FF44: 729.41176 | FG44: 371.76471 | FH44: 1101.1765 | FI44: 0 | FJ44: #REF! | FK44: #REF! | FL44: 0 | FM44: 141.17647 | FN44: #REF! | FO44: 37.647059 | FP44: #REF! | FR44: #REF!
A45: 0 | B45: 40217 | C45: 40217 | D45: 39489 | E45: 40217 | F45: 6 | H45: B | K45: 696.47059 | L45: 92.235294 | M45: 788.70588 | N45: 634.35294 | O45: 65.882353 | P45: 700.23529 | Q45: 10.352941 | R45: 0 | S45: 10.352941 | T45: 51.764706 | U45: 1148.2353 | V45: 1200 | W45: 696.47059 | X45: 1214.1176 | Y45: 1910.5882 | Z45: 2699.2941 | AA45: 1.9764706 | AB45: 0 | AC45: 1.9764706 | AD45: 0 | AE45: 0 | AF45: 0 | AG45: 4.6117647 | AH45: 0 | AI45: 4.6117647 | AJ45: 0 | AK45: 7.5294118 | AL45: 7.5294118 | AM45: 4.6117647 | AN45: 7.5294118 | AO45: 12.141176 | AP45: 14.117647 | AQ45: 0 | AR45: 790.68235 | AS45: 1922.7294 | AT45: 2713.4118 | AU45: 0 | AV45: 94.117647 | AW45: 37.647059 | AX45: 18.823529 | AY45: 150.58824 | AZ45: 0 | BA45: 0 | BB45: 57.411765 | BC45: 0 | BD45: 57.411765 | BE45: 57.411765 | BF45: 82.823529 | BG45: 140.23529 | BH45: 3004.2353 | BI45: 29836.529 | FE45: 40217 | FF45: 696.47059 | FG45: 634.35294 | FH45: 1330.8235 | FI45: 0 | FJ45: #REF! | FK45: #REF! | FL45: 0 | FM45: 94.117647 | FN45: #REF! | FO45: 18.823529 | FP45: #REF! | FR45: #REF!
A46: 0 | B46: 40218 | C46: 40218 | D46: 39490 | E46: 40218 | F46: 6 | H46: B | K46: 932.70588 | L46: 95.058824 | M46: 1027.7647 | N46: 381.17647 | O46: 47.058824 | P46: 428.23529 | Q46: 26.352941 | R46: 0 | S46: 26.352941 | T46: 32.941176 | U46: 1002.3529 | V46: 1035.2941 | W46: 440.47059 | X46: 1049.4118 | Y46: 1489.8824 | Z46: 2517.6471 | AA46: 1.6941176 | AB46: 1.4117647 | AC46: 3.1058824 | AD46: 0 | AE46: 0 | AF46: 0 | AG46: 3.9529412 | AH46: 3.2941176 | AI46: 7.2470588 | AJ46: 0 | AK46: 9.4117647 | AL46: 9.4117647 | AM46: 3.9529412 | AN46: 12.705882 | AO46: 16.658824 | AP46: 19.764706 | AQ46: 0 | AR46: 1030.8706 | AS46: 1506.5412 | AT46: 2537.4118 | AU46: 0 | AV46: 94.117647 | AW46: 65.882353 | AX46: 376.47059 | AY46: 536.47059 | AZ46: 0 | BA46: 0 | BB46: 0 | BC46: 0 | BD46: 0 | BE46: 0 | BF46: 281.41176 | BG46: 281.41176 | BH46: 3355.2941 | BI46: 33191.824 | FE46: 40218 | FF46: 932.70588 | FG46: 381.17647 | FH46: 1313.8824 | FI46: 0 | FJ46: #REF! | FK46: #REF! | FL46: 0 | FM46: 94.117647 | FN46: #REF! | FO46: 376.47059 | FP46: #REF! | FR46: #REF!
A47: 0 | B47: 40219 | C47: 40219 | D47: 39491 | E47: 40219 | F47: 6 | H47: B | K47: 545.88235 | L47: 98.823529 | M47: 644.70588 | N47: 481.88235 | O47: 53.647059 | P47: 535.52941 | Q47: 7.5294118 | R47: 0 | S47: 7.5294118 | T47: 77.176471 | U47: 734.11765 | V47: 811.29412 | W47: 566.58824 | X47: 787.76471 | Y47: 1354.3529 | Z47: 1999.0588 | AA47: 1.4117647 | AB47: 1.9764706 | AC47: 3.3882353 | AD47: 0 | AE47: 0 | AF47: 0 | AG47: 3.2941176 | AH47: 4.6117647 | AI47: 7.9058824 | AJ47: 0 | AK47: 9.4117647 | AL47: 9.4117647 | AM47: 3.2941176 | AN47: 14.023529 | AO47: 17.317647 | AP47: 20.705882 | AQ47: 0 | AR47: 648.09412 | AS47: 1371.6706 | AT47: 2019.7647 | AU47: 0 | AV47: 94.117647 | AW47: 0 | AX47: 65.882353 | AY47: 160 | AZ47: 0 | BA47: 0 | BB47: 0 | BC47: 0 | BD47: 0 | BE47: 0 | BF47: 457.41176 | BG47: 457.41176 | BH47: 2637.1765 | BI47: 35829 | FE47: 40219 | FF47: 545.88235 | FG47: 481.88235 | FH47: 1027.7647 | FI47: 0 | FJ47: #REF! | FK47: #REF! | FL47: 0 | FM47: 94.117647 | FN47: #REF! | FO47: 65.882353 | FP47: #REF! | FR47: #REF!
A48: 0 | B48: 40220 | C48: 40220 | D48: 39492 | E48: 40220 | F48: 6 | H48: B | K48: 743.52941 | L48: 96 | M48: 839.52941 | N48: 454.58824 | O48: 34.823529 | P48: 489.41176 | Q48: 4.7058824 | R48: 0 | S48: 4.7058824 | T48: 42.352941 | U48: 560 | V48: 602.35294 | W48: 501.64706 | X48: 594.82353 | Y48: 1096.4706 | Z48: 1936 | AA48: 2.8235294 | AB48: 1.4117647 | AC48: 4.2352941 | AD48: 0 | AE48: 0 | AF48: 0 | AG48: 6.5882353 | AH48: 3.2941176 | AI48: 9.8823529 | AJ48: 0 | AK48: 7.5294118 | AL48: 7.5294118 | AM48: 6.5882353 | AN48: 10.823529 | AO48: 17.411765 | AP48: 21.647059 | AQ48: 0 | AR48: 843.76471 | AS48: 1113.8824 | AT48: 1957.6471 | AU48: 0 | AV48: 94.117647 | AW48: 0 | AX48: 18.823529 | AY48: 112.94118 | AZ48: 0 | BA48: 0 | BB48: 0 | BC48: 0 | BD48: 0 | BE48: 0 | BF48: 327.52941 | BG48: 327.52941 | BH48: 2398.1176 | BI48: 38227.118 | FE48: 40220 | FF48: 743.52941 | FG48: 454.58824 | FH48: 1198.1176 | FI48: 0 | FJ48: #REF! | FK48: #REF! | FL48: 0 | FM48: 94.117647 | FN48: #REF! | FO48: 18.823529 | FP48: #REF! | FR48: #REF!
A49: 0 | B49: 40221 | C49: 40221 | D49: 39493 | E49: 40221 | F49: 6 | H49: B | K49: 687.05882 | L49: 92.235294 | M49: 779.29412 | N49: 786.82353 | O49: 17.882353 | P49: 804.70588 | Q49: 17.882353 | R49: 0 | S49: 17.882353 | T49: 108.23529 | U49: 1086.1176 | V49: 1194.3529 | W49: 912.94118 | X49: 1104 | Y49: 2016.9412 | Z49: 2796.2353 | AA49: 0.84705882 | AB49: 1.9764706 | AC49: 2.8235294 | AD49: 0 | AE49: 0 | AF49: 0 | AG49: 1.9764706 | AH49: 4.6117647 | AI49: 6.5882353 | AJ49: 0 | AK49: 10.352941 | AL49: 10.352941 | AM49: 1.9764706 | AN49: 14.964706 | AO49: 16.941176 | AP49: 19.764706 | AQ49: 0 | AR49: 782.11765 | AS49: 2033.8824 | AT49: 2816 | AU49: 0 | AV49: 94.117647 | AW49: 37.647059 | AX49: 451.76471 | AY49: 583.52941 | AZ49: 0 | BA49: 0 | BB49: 0 | BC49: 0 | BD49: 0 | BE49: 0 | BF49: 634.35294 | BG49: 634.35294 | BH49: 4033.8824 | BI49: 42261 | FE49: 40221 | FF49: 687.05882 | FG49: 786.82353 | FH49: 1473.8824 | FI49: 0 | FJ49: #REF! | FK49: #REF! | FL49: 0 | FM49: 94.117647 | FN49: #REF! | FO49: 451.76471 | FP49: #REF! | FR49: #REF!
A50: 0 | B50: 40222 | C50: 40222 | D50: 39494 | E50: 40222 | F50: 6 | H50: BA | K50: 1458.8235 | L50: 334.11765 | M50: 1792.9412 | N50: 547.76471 | O50: 33.882353 | P50: 581.64706 | Q50: 4.7058824 | R50: 0 | S50: 4.7058824 | T50: 51.764706 | U50: 1185.8824 | V50: 1237.6471 | W50: 604.23529 | X50: 1219.7647 | Y50: 1824 | Z50: 3616.9412 | AA50: 5.3647059 | AB50: 0.56470588 | AC50: 5.9294118 | AD50: 0 | AE50: 0 | AF50: 0 | AG50: 12.517647 | AH50: 1.3176471 | AI50: 13.835294 | AJ50: 1.8823529 | AK50: 13.176471 | AL50: 15.058824 | AM50: 14.4 | AN50: 14.494118 | AO50: 28.894118 | AP50: 34.823529 | AQ50: 0 | AR50: 1798.8706 | AS50: 1852.8941 | AT50: 3651.7647 | AU50: 0 | AV50: 141.17647 | AW50: 0 | AX50: 56.470588 | AY50: 197.64706 | AZ50: 0 | BA50: 0 | BB50: 178.82353 | BC50: 0 | BD50: 178.82353 | BE50: 178.82353 | BF50: 384.94118 | BG50: 563.76471 | BH50: 4413.1765 | BI50: 46674.176 | FE50: 40222 | FF50: 1458.8235 | FG50: 547.76471 | FH50: 2006.5882 | FI50: 0 | FJ50: #REF! | FK50: #REF! | FL50: 0 | FM50: 141.17647 | FN50: #REF! | FO50: 56.470588 | FP50: #REF! | FR50: #REF!
A51: 0 | B51: 40223 | C51: 40223 | D51: 39495 | E51: 40223 | F51: 6 | H51: BA | K51: 1167.0588 | L51: 346.35294 | M51: 1513.4118 | N51: 629.64706 | O51: 65.882353 | P51: 695.52941 | Q51: 16.941176 | R51: 0 | S51: 16.941176 | T51: 102.58824 | U51: 1829.6471 | V51: 1932.2353 | W51: 749.17647 | X51: 1895.5294 | Y51: 2644.7059 | Z51: 4158.1176 | AA51: 1.9764706 | AB51: 0 | AC51: 1.9764706 | AD51: 0 | AE51: 0 | AF51: 0 | AG51: 4.6117647 | AH51: 0 | AI51: 4.6117647 | AJ51: 0 | AK51: 11.294118 | AL51: 11.294118 | AM51: 4.6117647 | AN51: 11.294118 | AO51: 15.905882 | AP51: 17.882353 | AQ51: 0 | AR51: 1515.3882 | AS51: 2660.6118 | AT51: 4176 | AU51: 0 | AV51: 94.117647 | AW51: 0 | AX51: 75.294118 | AY51: 169.41176 | AZ51: 0 | BA51: 0 | BB51: 193.88235 | BC51: 0 | BD51: 193.88235 | BE51: 193.88235 | BF51: 49.882353 | BG51: 243.76471 | BH51: 4589.1765 | BI51: 51263.353 | FE51: 40223 | FF51: 1167.0588 | FG51: 629.64706 | FH51: 1796.7059 | FI51: 0 | FJ51: #REF! | FK51: #REF! | FL51: 0 | FM51: 94.117647 | FN51: #REF! | FO51: 75.294118 | FP51: #REF! | FR51: #REF!
A52: 0 | B52: 40224 | C52: 40224 | D52: 39496 | E52: 40224 | F52: 7 | H52: BA | K52: 672.94118 | L52: 127.05882 | M52: 800 | N52: 813.17647 | O52: 94.117647 | P52: 907.29412 | Q52: 19.764706 | R52: 0 | S52: 19.764706 | T52: 70.588235 | U52: 1874.8235 | V52: 1945.4118 | W52: 903.52941 | X52: 1968.9412 | Y52: 2872.4706 | Z52: 3672.4706 | AA52: 6.2117647 | AB52: 8.4705882 | AC52: 14.682353 | AD52: 0 | AE52: 0 | AF52: 0 | AG52: 14.494118 | AH52: 19.764706 | AI52: 34.258824 | AJ52: 0 | AK52: 72.470588 | AL52: 72.470588 | AM52: 14.494118 | AN52: 92.235294 | AO52: 106.72941 | AP52: 121.41176 | AQ52: 0 | AR52: 814.68235 | AS52: 2979.2 | AT52: 3793.8824 | AU52: 0 | AV52: 94.117647 | AW52: 0 | AX52: 18.823529 | AY52: 112.94118 | AZ52: 0 | BA52: 0 | BB52: 0 | BC52: 0 | BD52: 0 | BE52: 0 | BF52: 14.117647 | BG52: 14.117647 | BH52: 3920.9412 | BI52: 55184.294 | FE52: 40224 | FF52: 672.94118 | FG52: 813.17647 | FH52: 1486.1176 | FI52: 0 | FJ52: #REF! | FK52: #REF! | FL52: 0 | FM52: 94.117647 | FN52: #REF! | FO52: 18.823529 | FP52: #REF! | FR52: #REF!
A53: 0 | B53: 40225 | C53: 40225 | D53: 39497 | E53: 40225 | F53: 7 | H53: BA | K53: 933.64706 | L53: 190.11765 | M53: 1123.7647 | N53: 680.47059 | O53: 92.235294 | P53: 772.70588 | Q53: 30.117647 | R53: 0 | S53: 30.117647 | T53: 116.70588 | U53: 2588.2353 | V53: 2704.9412 | W53: 827.29412 | X53: 2680.4706 | Y53: 3507.7647 | Z53: 4631.5294 | AA53: 11.858824 | AB53: 9.3176471 | AC53: 21.176471 | AD53: 0 | AE53: 0 | AF53: 0 | AG53: 27.670588 | AH53: 21.741176 | AI53: 49.411765 | AJ53: 0 | AK53: 51.764706 | AL53: 51.764706 | AM53: 27.670588 | AN53: 73.505882 | AO53: 101.17647 | AP53: 122.35294 | AQ53: 0 | AR53: 1144.9412 | AS53: 3608.9412 | AT53: 4753.8824 | AU53: 0 | AV53: 94.117647 | AW53: 0 | AX53: 470.58824 | AY53: 564.70588 | AZ53: 0 | BA53: 0 | BB53: 0 | BC53: 0 | BD53: 0 | BE53: 0 | BF53: 197.64706 | BG53: 197.64706 | BH53: 5516.2353 | BI53: 60700.529 | FE53: 40225 | FF53: 933.64706 | FG53: 680.47059 | FH53: 1614.1176 | FI53: 0 | FJ53: #REF! | FK53: #REF! | FL53: 0 | FM53: 94.117647 | FN53: #REF! | FO53: 470.58824 | FP53: #REF! | FR53: #REF!
A54: 0 | B54: 40226 | C54: 40226 | D54: 39498 | E54: 40226 | F54: 7 | H54: BA | K54: 892.23529 | L54: 199.52941 | M54: 1091.7647 | N54: 759.52941 | O54: 66.823529 | P54: 826.35294 | Q54: 9.4117647 | R54: 0 | S54: 9.4117647 | T54: 135.52941 | U54: 2127.0588 | V54: 2262.5882 | W54: 904.47059 | X54: 2193.8824 | Y54: 3098.3529 | Z54: 4190.1176 | AA54: 12.705882 | AB54: 5.6470588 | AC54: 18.352941 | AD54: 0 | AE54: 0 | AF54: 0 | AG54: 29.647059 | AH54: 13.176471 | AI54: 42.823529 | AJ54: 0 | AK54: 31.058824 | AL54: 31.058824 | AM54: 29.647059 | AN54: 44.235294 | AO54: 73.882353 | AP54: 92.235294 | AQ54: 0 | AR54: 1110.1176 | AS54: 3172.2353 | AT54: 4282.3529 | AU54: 0 | AV54: 94.117647 | AW54: 0 | AX54: 112.94118 | AY54: 207.05882 | AZ54: 0 | BA54: 0 | BB54: 65.882353 | BC54: 0 | BD54: 65.882353 | BE54: 65.882353 | BF54: 120.47059 | BG54: 186.35294 | BH54: 4675.7647 | BI54: 65376.294 | FE54: 40226 | FF54: 892.23529 | FG54: 759.52941 | FH54: 1651.7647 | FI54: 0 | FJ54: #REF! | FK54: #REF! | FL54: 0 | FM54: 94.117647 | FN54: #REF! | FO54: 112.94118 | FP54: #REF! | FR54: #REF!
... A65: 0 | B65: 40237 | C65: 40237 | D65: 39509 | E65: 40237 | F65: 8 | H65: AC | K65: 701.17647 | L65: 183.52941 | M65: 884.70588 | N65: 600.47059 | O65: 82.823529 | P65: 683.29412 | Q65: 24.470588 | R65: 0 | S65: 24.470588 | T65: 114.82353 | U65: 1621.6471 | V65: 1736.4706 | W65: 739.76471 | X65: 1704.4706 | Y65: 2444.2353 | Z65: 3328.9412 | AA65: 2.2588235 | AB65: 1.6941176 | AC65: 3.9529412 | AD65: 0 | AE65: 0 | AF65: 0 | AG65: 5.2705882 | AH65: 3.9529412 | AI65: 9.2235294 | AJ65: 6.5882353 | AK65: 32.941176 | AL65: 39.529412 | AM65: 11.858824 | AN65: 36.894118 | AO65: 48.752941 | AP65: 52.705882 | AQ65: 0 | AR65: 888.65882 | AS65: 2492.9882 | AT65: 3381.6471 | AU65: 0 | AV65: 70.588235 | AW65: 0 | AX65: 47.058824 | AY65: 117.64706 | AZ65: 0 | BA65: 98.823529 | BB65: 291.76471 | BC65: 98.823529 | BD65: 291.76471 | BE65: 390.58824 | BF65: 23.529412 | BG65: 414.11765 | BH65: 3913.4118 | BI65: 115975.82 | FE65: 40237 | FF65: 701.17647 | FG65: 600.47059 | FH65: 1301.6471 | FI65: 98.823529 | FJ65: #REF! | FK65: #REF! | FL65: 0 | FM65: 70.588235 | FN65: #REF! | FO65: 47.058824 | FP65: #REF! | FR65: #REF!
AT66: 0 | AY66: 0
...

Sheet Cognos_Office_Connection_Cache

Sheet Janvier
A1: 45292 | B1: HORAIRES ET PREVISIONS DE FREQUENTATION
A3: Jour | B3: =+A1 -> 45292 | C3: =+B3+1 -> 45293 | D3: =+C3+1 -> 45294 | E3: =+D3+1 -> 45295 | F3: =+E3+1 -> 45296 | G3: =+F3+1 -> 45297 | H3: =+G3+1 -> 45298 | I3: =+H3+1 -> 45299 | J3: =+I3+1 -> 45300 | ... AF3: =+AE3+1 -> 45322
A4: Date | B4: =+A1 -> 45292 | C4: =+B4+1 -> 45293 | D4: =+C4+1 -> 45294 | E4: =+D4+1 -> 45295 | F4: =+E4+1 -> 45296 | G4: =+F4+1 -> 45297 | H4: =+G4+1 -> 45298 | I4: =+H4+1 -> 45299 | J4: =+I4+1 -> 45300 | ... AF4: =+AE4+1 -> 45322
A6: JF | B6: Nouvel An
A7: VAC | B7: ABC | C7: ABC | D7: ABC | E7: ABC | F7: ABC | G7: ABC | H7: ABC
A8: H. ouv. Passerelle Hôtel | B8: 0.39583333 | C8: 0.39583333 | D8: 0.39583333 | E8: 0.39583333 | F8: 0.39583333 | G8: 0.39583333 | H8: 0.39583333 | I8: =I9 | J8: =J9 | K8: =K9 | L8: =L9 | M8: =M9 | N8: =N9 | O8: =O9 | P8: =P9 | ... AF8: =AF9
A9: H. ouv. Entrée du Parc | B9: 0.38541667 | C9: 0.38541667 | D9: 0.38541667 | E9: 0.38541667 | F9: 0.38541667 | G9: 0.38541667 | H9: 0.38541667 | I9: =IF(I10="","",I10-"0:15") | J9: =IF(J10="","",J10-"0:15") | K9: =IF(K10="","",K10-"0:15") | L9: =IF(L10="","",L10-"0:15") | M9: =IF(M10="","",M10-"0:15") | N9: =IF(N10="","",N10-"0:15") | O9: =IF(O10="","",O10-"0:15") | P9: =IF(P10="","",P10-"0:15") | ... AF9: =IF(AF10="","",AF10-"0:15")
A10: H. Ouv. | B10: 0.39583333 | C10: 0.39583333 | D10: 0.39583333 | E10: 0.39583333 | F10: 0.39583333 | G10: 0.39583333 | H10: 0.39583333
A11: H. Ferm | B11: =IF(B10="","",IF(B15=0,B14+"0:30",+B15+"0:30")) -> 0.91666667 | C11: =IF(C10="","",IF(C15=0,C14+"0:30",+C15+"0:30")) -> 0.91666667 | D11: =IF(D10="","",IF(D15=0,D14+"0:30",+D15+"0:30")) -> 0.91666667 | E11: =IF(E10="","",IF(E15=0,E14+"0:30",+E15+"0:30")) -> 0.91666667 | F11: =IF(F10="","",IF(F15=0,F14+"0:30",+F15+"0:30")) -> 0.91666667 | G11: =IF(G10="","",IF(G15=0,G14+"0:30",+G15+"0:30")) -> 0.91666667 | H11: =IF(H10="","",IF(H15=0,H14+"0:30",+H15+"0:30")) -> 0.77083333 | I11: =IF(I10="","",IF(I15=0,I14+"0:30",+I15+"0:30")) | ... AF11: =IF(AF10="","",IF(AF15=0,AF14+"0:30",+AF15+"0:30"))
A12: Ampl. Hor. | B12: =+IF(B10="","",(B11-B10)) -> 0.52083333 | C12: =+IF(C10="","",(C11-C10)) -> 0.52083333 | D12: =+IF(D10="","",(D11-D10)) -> 0.52083333 | E12: =+IF(E10="","",(E11-E10)) -> 0.52083333 | F12: =+IF(F10="","",(F11-F10)) -> 0.52083333 | G12: =+IF(G10="","",(G11-G10)) -> 0.52083333 | H12: =+IF(H10="","",(H11-H10)) -> 0.375 | I12: =+IF(I10="","",(I11-I10)) | ... AF12: =+IF(AF10="","",(AF11-AF10)) | AH12: =SUM(B12:AF12) -> 3.5
A14: 1er show | B14: 0.86458333 | C14: 0.86458333 | D14: 0.86458333 | E14: 0.86458333 | F14: 0.89583333 | G14: 0.89583333 | H14: 0.75
A15: 2nd show | B15: 0.89583333 | C15: 0.89583333 | D15: 0.89583333 | E15: 0.89583333
A16: Show Privatisé
A17: Nb 1er Show | B17: =+IF(B14<>"",1,0) -> 1 | C17: =+IF(C14<>"",1,0) -> 1 | D17: =+IF(D14<>"",1,0) -> 1 | E17: =+IF(E14<>"",1,0) -> 1 | F17: =+IF(F14<>"",1,0) -> 1 | G17: =+IF(G14<>"",1,0) -> 1 | H17: =+IF(H14<>"",1,0) -> 1 | I17: =+IF(I14<>"",1,0) -> 0 | ... AF17: =+IF(AF14<>"",1,0) -> 0
A18: Nb 2eme Show | B18: =+IF(B15<>"",1,0) -> 1 | C18: =+IF(C15<>"",1,0) -> 1 | D18: =+IF(D15<>"",1,0) -> 1 | E18: =+IF(E15<>"",1,0) -> 1 | F18: =+IF(F15<>"",1,0) -> 0 | G18: =+IF(G15<>"",1,0) -> 0 | H18: =+IF(H15<>"",1,0) -> 0 | I18: =+IF(I15<>"",1,0) -> 0 | ... AF18: =+IF(AF15<>"",1,0) -> 0
A19: Nb show privatisé | B19: =+IF(B16<>"",1,0) -> 0 | C19: =+IF(C16<>"",1,0) -> 0 | D19: =+IF(D16<>"",1,0) -> 0 | E19: =+IF(E16<>"",1,0) -> 0 | F19: =+IF(F16<>"",1,0) -> 0 | I19: =+IF(I16<>"",1,0) -> 0 | J19: =+IF(J16<>"",1,0) -> 0 | K19: =+IF(K16<>"",1,0) -> 0 | L19: =+IF(L16<>"",1,0) -> 0 | M19: =+IF(M16<>"",1,0) -> 0 | N19: =+IF(N16<>"",1,0) -> 0 | O19: =+IF(O16<>"",1,0) -> 0 | P19: =+IF(P16<>"",1,0) -> 0 | ... AF19: =+IF(AF16<>"",1,0) -> 0
A20: Nb Spectacles | B20: =IF(B14="","",SUM(B17:B19)) -> 2 | C20: =IF(C14="","",SUM(C17:C19)) -> 2 | D20: =IF(D14="","",SUM(D17:D19)) -> 2 | E20: =IF(E14="","",SUM(E17:E19)) -> 2 | F20: =IF(F14="","",SUM(F17:F19)) -> 1 | G20: =IF(G14="","",SUM(G17:G19)) -> 1 | H20: =IF(H14="","",SUM(H17:H19)) -> 1 | I20: =I19+I18+I17 -> 0 | J20: =J19+J18+J17 -> 0 | K20: =K19+K18+K17 -> 0 | L20: =L19+L18+L17 -> 0 | M20: =M19+M18+M17 -> 0 | N20: =N19+N18+N17 -> 0 | O20: =O19+O18+O17 -> 0 | P20: =P19+P18+P17 -> 0 | ... AF20: =AF19+AF18+AF17 -> 0 | AH20: =SUM(B20:AF20) -> 11
A22: Individuels cash | B22: 2100 | C22: 1900 | D22: 1600 | E22: 1600 | F22: 1200 | G22: 1300 | H22: 700 | AH22: =SUM(B22:AG22) -> 10400
A23: Individuels résa | B23: 6800 | C23: 5500 | D23: 7600 | E23: 7200 | F23: 4600 | G23: 4600 | H23: 1900 | AH23: =SUM(B23:AG23) -> 38200
A24: Total Individuels | B24: 8900 | C24: 7400 | D24: 9200 | E24: 8800 | F24: 5800 | G24: 5900 | H24: 2600 | I24: 0 | J24: 0 | K24: 0 | L24: 0 | M24: 0 | N24: 0 | O24: 0 | P24: 0 | Q24: 0 | R24: 0 | S24: 0 | T24: 0 | U24: 0 | V24: 0 | W24: 0 | X24: 0 | Y24: 0 | Z24: 0 | AA24: 0 | AB24: 0 | AC24: 0 | AD24: 0 | AE24: 0 | AF24: 0 | AH24: =SUM(B24:AG24) -> 48600
A25: Groupes Adultes | B25: 0 | C25: 20 | D25: 0 | E25: 30 | F25: 0 | G25: 20 | H25: 20 | AH25: =SUM(B25:AG25) -> 90
A26: Groupes Jeunes | B26: 0 | C26: 60 | D26: 140 | E26: 40 | F26: 160 | G26: 20 | H26: 0 | AH26: =SUM(B26:AG26) -> 420
A27: Groupes | B27: 0 | C27: 80 | D27: 140 | E27: 70 | F27: 160 | G27: 40 | H27: 20 | I27: 0 | J27: 0 | K27: 0 | L27: 0 | M27: 0 | N27: 0 | O27: 0 | P27: 0 | Q27: 0 | R27: 0 | S27: 0 | T27: 0 | U27: 0 | V27: 0 | W27: 0 | X27: 0 | Y27: 0 | Z27: 0 | AA27: 0 | AB27: 0 | AC27: 0 | AD27: 0 | AE27: 0 | AF27: 0 | AH27: =SUM(B27:AG27) -> 510
A28: Nocturnes | B28: 90 | C28: 70 | D28: 70 | E28: 70 | F28: 50 | G28: 40 | H28: 40 | AH28: =SUM(B28:AG28) -> 430
A29: Pass | B29: 160 | C29: 130 | D29: 150 | E29: 130 | F29: 90 | G29: 70 | H29: 70 | AH29: =SUM(B29:AG29) -> 800
A30: Tourisme d'Affaires | B30: 0 | C30: 0 | D30: 0 | E30: 0 | F30: 0 | G30: 0 | H30: 120 | I30: 600 | J30: 200 | K30: 0 | L30: 0 | M30: 0 | N30: 0 | O30: 0 | P30: 0 | Q30: 0 | R30: 0 | S30: 0 | T30: 0 | U30: 0 | V30: 0 | W30: 300 | X30: 400 | Y30: 0 | Z30: 0 | AA30: 0 | AB30: 0 | AC30: 0 | AD30: 0 | AE30: 0 | AF30: 0 | AH30: =SUM(B30:AG30) -> 1620
A31: Invités | B31: 300 | C31: 500 | D31: 500 | E31: 600 | F31: 400 | G31: 400 | H31: 400 | AH31: =SUM(B31:AG31) -> 3100
A32: Total Divers | B32: 550 | C32: 700 | D32: 720 | E32: 800 | F32: 540 | G32: 510 | H32: 630 | I32: 600 | J32: 200 | K32: 0 | L32: 0 | M32: 0 | N32: 0 | O32: 0 | P32: 0 | Q32: 0 | R32: 0 | S32: 0 | T32: 0 | U32: 0 | V32: 0 | W32: 300 | X32: 400 | Y32: 0 | Z32: 0 | AA32: 0 | AB32: 0 | AC32: 0 | AD32: 0 | AE32: 0 | AF32: 0 | AH32: =SUM(B32:AG32) -> 5950
A34: Fréquentation | B34: =+B32+B27+B24 -> 9450 | C34: =+C32+C27+C24 -> 8180 | D34: =+D32+D27+D24 -> 10060 | E34: =+E32+E27+E24 -> 9670 | F34: =+F32+F27+F24 -> 6500 | G34: =+G32+G27+G24 -> 6450 | H34: =+H32+H27+H24 -> 3250 | I34: =+I32+I27+I24 -> 600 | ... AF34: =+AF32+AF27+AF24 -> 0 | AH34: =SUM(B34:AF34) -> 55060
A37: Crépuscule civil | B37: 0.74722222 | C37: 0.74791667 | D37: 0.74861111 | E37: 0.74861111 | F37: 0.74930556 | G37: 0.75 | H37: 0.75069444 | I37: 0.75208333 | J37: 0.75277778 | K37: 0.75347222 | L37: 0.75416667 | M37: 0.75486111 | N37: 0.75555556 | O37: 0.75625 | P37: 0.75763889 | Q37: 0.75833333 | R37: 0.75902778 | S37: 0.75972222 | T37: 0.76111111 | U37: 0.76180556 | V37: 0.76319444 | W37: 0.76388889 | X37: 0.76458333 | Y37: 0.76527778 | Z37: 0.76666667 | AA37: 0.76736111 | AB37: 0.76805556 | AC37: 0.76944444 | AD37: 0.77013889 | AE37: 0.77152778 | AF37: 0.77222222
A38: Type Fréquentation | B38: =+IF(B34<=2500,"BF",IF(AND(B34>2500,B34<=6000),"MF",IF(AND(B34>6000,B34<12000),"HF","THF"))) -> HF | C38: =+IF(C34<=2500,"BF",IF(AND(C34>2500,C34<=6000),"MF",IF(AND(C34>6000,C34<12000),"HF","THF"))) -> HF | D38: =+IF(D34<=2500,"BF",IF(AND(D34>2500,D34<=6000),"MF",IF(AND(D34>6000,D34<12000),"HF","THF"))) -> HF | E38: =+IF(E34<=2500,"BF",IF(AND(E34>2500,E34<=6000),"MF",IF(AND(E34>6000,E34<12000),"HF","THF"))) -> HF | F38: =+IF(F34<=2500,"BF",IF(AND(F34>2500,F34<=6000),"MF",IF(AND(F34>6000,F34<12000),"HF","THF"))) -> HF | G38: =+IF(G34<=2500,"BF",IF(AND(G34>2500,G34<=6000),"MF",IF(AND(G34>6000,G34<12000),"HF","THF"))) -> HF | H38: =+IF(H34<=2500,"BF",IF(AND(H34>2500,H34<=6000),"MF",IF(AND(H34>6000,H34<12000),"HF","THF"))) -> MF | I38: =+IF(I34<=2500,"BF",IF(AND(I34>2500,I34<=6000),"MF",IF(AND(I34>6000,I34<12000),"HF","THF"))) -> BF | ... AF38: =+IF(AF34<=2500,"BF",IF(AND(AF34>2500,AF34<=6000),"MF",IF(AND(AF34>6000,AF34<12000),"HF","THF"))) -> BF
B41: =+B34-B30 -> 9450 | C41: =+C34-C30 -> 8180 | D41: =+D34-D30 -> 10060 | E41: =+E34-E30 -> 9670 | F41: =+F34-F30 -> 6500 | G41: =+G34-G30 -> 6450 | H41: =+H34-H30 -> 3130 | I41: =+I34-I30 -> 0 | ... AE41: =+AE34-AE30 -> 0
B42: =+B32-B30 -> 550 | C42: =+C32-C30 -> 700 | D42: =+D32-D30 -> 720 | E42: =+E32-E30 -> 800 | F42: =+F32-F30 -> 540 | G42: =+G32-G30 -> 510 | H42: =+H32-H30 -> 510 | I42: =+I32-I30 -> 0 | ... AF42: =+AF32-AF30 -> 0
